Workbook

Sheet Dataset Asli
A1: DATASET ASLI - DRUG200 (200 DATA)
A3: Age | B3: BP | C3: Cholesterol | D3: Na_to_K | E3: ClassDrug
A4: YOUNG | B4: HIGH | C4: HIGH | D4: NORMAL | E4: drugA
A5: YOUNG | B5: HIGH | C5: HIGH | D5: NORMAL | E5: drugA
A6: YOUNG | B6: HIGH | C6: HIGH | D6: LOW | E6: drugA
A7: YOUNG | B7: HIGH | C7: NORMAL | D7: LOW | E7: drugA
A8: ADULT | B8: HIGH | C8: NORMAL | D8: NORMAL | E8: drugA
A9: ADULT | B9: HIGH | C9: HIGH | D9: NORMAL | E9: drugA
A10: ADULT | B10: HIGH | C10: NORMAL | D10: NORMAL | E10: drugA
A11: ADULT | B11: HIGH | C11: NORMAL | D11: NORMAL | E11: drugA
A12: ADULT | B12: HIGH | C12: NORMAL | D12: LOW | E12: drugA
A13: ADULT | B13: HIGH | C13: NORMAL | D13: NORMAL | E13: drugA
A14: ADULT | B14: HIGH | C14: HIGH | D14: NORMAL | E14: drugA
... A203: OLD | B203: LOW | C203: HIGH | D203: HIGH | E203: DrugY

Sheet Splitting Data
A1: STRATIFIED SPLIT 80:20 (TRAIN 160 / TEST 40)
A2: Metode: stratified sampling per kelas ClassDrug, random_state=42, proporsi kelas dijaga sama seperti data asli.
A4: No | B4: Age | C4: BP | D4: Cholesterol | E4: Na_to_K | F4: ClassDrug | G4: Set | H4: Baris Asal (Dataset Asli)
A5: 1 | B5: YOUNG | C5: HIGH | D5: HIGH | E5: NORMAL | F5: drugA | G5: Train | H5: 2
A6: 2 | B6: YOUNG | C6: HIGH | D6: HIGH | E6: LOW | F6: drugA | G6: Train | H6: 3
A7: 3 | B7: YOUNG | C7: HIGH | D7: NORMAL | E7: LOW | F7: drugA | G7: Train | H7: 4
A8: 4 | B8: ADULT | C8: HIGH | D8: NORMAL | E8: NORMAL | F8: drugA | G8: Train | H8: 5
A9: 5 | B9: ADULT | C9: HIGH | D9: HIGH | E9: NORMAL | F9: drugA | G9: Train | H9: 6
A10: 6 | B10: ADULT | C10: HIGH | D10: NORMAL | E10: NORMAL | F10: drugA | G10: Train | H10: 7
A11: 7 | B11: ADULT | C11: HIGH | D11: NORMAL | E11: LOW | F11: drugA | G11: Train | H11: 9
A12: 8 | B12: ADULT | C12: HIGH | D12: NORMAL | E12: NORMAL | F12: drugA | G12: Train | H12: 10
A13: 9 | B13: ADULT | C13: HIGH | D13: HIGH | E13: NORMAL | F13: drugA | G13: Train | H13: 13
A14: 10 | B14: ADULT | C14: HIGH | D14: NORMAL | E14: NORMAL | F14: drugA | G14: Train | H14: 14
A15: 11 | B15: ADULT | C15: HIGH | D15: HIGH | E15: LOW | F15: drugA | G15: Train | H15: 15
A16: 12 | B16: ADULT | C16: HIGH | D16: NORMAL | E16: NORMAL | F16: drugA | G16: Train | H16: 16
... A204: 200 | B204: OLD | C204: LOW | D204: HIGH | E204: NORMAL | F204: DrugY | G204: Test | H204: 194

Sheet Prior & Likelihood
A1: PRIOR & LIKELIHOOD - DIHITUNG DARI 160 DATA TRAIN
A2: Sumber data: sheet Splitting Data, baris 5-164 (Set = Train). Struktur tabel sama persis seperti simulasi manual, hanya sumber datanya diganti.
A3: 1. TABEL PRIOR P(Kelas) - dari Train
A4: Kelas | B4: Jumlah | C4: Prior
A5: drugA | B5: =COUNTIF('Splitting Data'!$F$5:$F$164,A5) -> 18 | C5: =B5/$B$10 -> 0.1125
A6: drugB | B6: =COUNTIF('Splitting Data'!$F$5:$F$164,A6) -> 13 | C6: =B6/$B$10 -> 0.08125
A7: drugC | B7: =COUNTIF('Splitting Data'!$F$5:$F$164,A7) -> 13 | C7: =B7/$B$10 -> 0.08125
A8: drugX | B8: =COUNTIF('Splitting Data'!$F$5:$F$164,A8) -> 43 | C8: =B8/$B$10 -> 0.26875
A9: DrugY | B9: =COUNTIF('Splitting Data'!$F$5:$F$164,A9) -> 73 | C9: =B9/$B$10 -> 0.45625
A10: Total | B10: =SUM(B5:B9) -> 160 | C10: =SUM(C5:C9) -> 1
A13: 2. TABEL KONTINGENSI & LIKELIHOOD - AGE
A14: Kelas | B14: YOUNG | C14: ADULT | D14: OLD | E14: Total
A15: drugA | B15: =COUNTIFS('Splitting Data'!$F$5:$F$164,$A15,'Splitting Data'!$B$5:$B$164,B$14) -> 3 | C15: =COUNTIFS('Splitting Data'!$F$5:$F$164,$A15,'Splitting Data'!$B$5:$B$164,C$14) -> 10 | D15: =COUNTIFS('Splitting Data'!$F$5:$F$164,$A15,'Splitting Data'!$B$5:$B$164,D$14) -> 5 | E15: =SUM(B15:D15) -> 18
A16: drugB | B16: =COUNTIFS('Splitting Data'!$F$5:$F$164,$A16,'Splitting Data'!$B$5:$B$164,B$14) -> 0 | C16: =COUNTIFS('Splitting Data'!$F$5:$F$164,$A16,'Splitting Data'!$B$5:$B$164,C$14) -> 0 | D16: =COUNTIFS('Splitting Data'!$F$5:$F$164,$A16,'Splitting Data'!$B$5:$B$164,D$14) -> 13 | E16: =SUM(B16:D16) -> 13
A17: drugC | B17: =COUNTIFS('Splitting Data'!$F$5:$F$164,$A17,'Splitting Data'!$B$5:$B$164,B$14) -> 1 | C17: =COUNTIFS('Splitting Data'!$F$5:$F$164,$A17,'Splitting Data'!$B$5:$B$164,C$14) -> 3 | D17: =COUNTIFS('Splitting Data'!$F$5:$F$164,$A17,'Splitting Data'!$B$5:$B$164,D$14) -> 9 | E17: =SUM(B17:D17) -> 13
A18: drugX | B18: =COUNTIFS('Splitting Data'!$F$5:$F$164,$A18,'Splitting Data'!$B$5:$B$164,B$14) -> 9 | C18: =COUNTIFS('Splitting Data'!$F$5:$F$164,$A18,'Splitting Data'!$B$5:$B$164,C$14) -> 12 | D18: =COUNTIFS('Splitting Data'!$F$5:$F$164,$A18,'Splitting Data'!$B$5:$B$164,D$14) -> 22 | E18: =SUM(B18:D18) -> 43
A19: DrugY | B19: =COUNTIFS('Splitting Data'!$F$5:$F$164,$A19,'Splitting Data'!$B$5:$B$164,B$14) -> 13 | C19: =COUNTIFS('Splitting Data'!$F$5:$F$164,$A19,'Splitting Data'!$B$5:$B$164,C$14) -> 28 | D19: =COUNTIFS('Splitting Data'!$F$5:$F$164,$A19,'Splitting Data'!$B$5:$B$164,D$14) -> 32 | E19: =SUM(B19:D19) -> 73
A20: Total | B20: =SUM(B15:B19) -> 26 | C20: =SUM(C15:C19) -> 53 | D20: =SUM(D15:D19) -> 81 | E20: =SUM(E15:E19) -> 160
A22: LIKELIHOOD P(Age | Kelas)
A23: Kelas | B23: YOUNG | C23: ADULT | D23: OLD
A24: drugA | B24: =B15/E15 -> 0.16666667 | C24: =C15/E15 -> 0.55555556 | D24: =D15/E15 -> 0.27777778
A25: drugB | B25: =B16/E16 -> 0 | C25: =C16/E16 -> 0 | D25: =D16/E16 -> 1
A26: drugC | B26: =B17/E17 -> 0.076923077 | C26: =C17/E17 -> 0.23076923 | D26: =D17/E17 -> 0.69230769
A27: drugX | B27: =B18/E18 -> 0.20930233 | C27: =C18/E18 -> 0.27906977 | D27: =D18/E18 -> 0.51162791
A28: DrugY | B28: =B19/E19 -> 0.17808219 | C28: =C19/E19 -> 0.38356164 | D28: =D19/E19 -> 0.43835616
A31: 3. TABEL KONTINGENSI & LIKELIHOOD - BP
A32: Kelas | B32: HIGH | C32: LOW | D32: NORMAL | E32: Total
A33: drugA | B33: =COUNTIFS('Splitting Data'!$F$5:$F$164,$A33,'Splitting Data'!$C$5:$C$164,B$32) -> 18 | C33: =COUNTIFS('Splitting Data'!$F$5:$F$164,$A33,'Splitting Data'!$C$5:$C$164,C$32) -> 0 | D33: =COUNTIFS('Splitting Data'!$F$5:$F$164,$A33,'Splitting Data'!$C$5:$C$164,D$32) -> 0 | E33: =SUM(B33:D33) -> 18
A34: drugB | B34: =COUNTIFS('Splitting Data'!$F$5:$F$164,$A34,'Splitting Data'!$C$5:$C$164,B$32) -> 13 | C34: =COUNTIFS('Splitting Data'!$F$5:$F$164,$A34,'Splitting Data'!$C$5:$C$164,C$32) -> 0 | D34: =COUNTIFS('Splitting Data'!$F$5:$F$164,$A34,'Splitting Data'!$C$5:$C$164,D$32) -> 0 | E34: =SUM(B34:D34) -> 13
A35: drugC | B35: =COUNTIFS('Splitting Data'!$F$5:$F$164,$A35,'Splitting Data'!$C$5:$C$164,B$32) -> 0 | C35: =COUNTIFS('Splitting Data'!$F$5:$F$164,$A35,'Splitting Data'!$C$5:$C$164,C$32) -> 13 | D35: =COUNTIFS('Splitting Data'!$F$5:$F$164,$A35,'Splitting Data'!$C$5:$C$164,D$32) -> 0 | E35: =SUM(B35:D35) -> 13
A36: drugX | B36: =COUNTIFS('Splitting Data'!$F$5:$F$164,$A36,'Splitting Data'!$C$5:$C$164,B$32) -> 0 | C36: =COUNTIFS('Splitting Data'!$F$5:$F$164,$A36,'Splitting Data'!$C$5:$C$164,C$32) -> 14 | D36: =COUNTIFS('Splitting Data'!$F$5:$F$164,$A36,'Splitting Data'!$C$5:$C$164,D$32) -> 29 | E36: =SUM(B36:D36) -> 43
A37: DrugY | B37: =COUNTIFS('Splitting Data'!$F$5:$F$164,$A37,'Splitting Data'!$C$5:$C$164,B$32) -> 31 | C37: =COUNTIFS('Splitting Data'!$F$5:$F$164,$A37,'Splitting Data'!$C$5:$C$164,C$32) -> 21 | D37: =COUNTIFS('Splitting Data'!$F$5:$F$164,$A37,'Splitting Data'!$C$5:$C$164,D$32) -> 21 | E37: =SUM(B37:D37) -> 73
A38: Total | B38: =SUM(B33:B37) -> 62 | C38: =SUM(C33:C37) -> 48 | D38: =SUM(D33:D37) -> 50 | E38: =SUM(E33:E37) -> 160
A40: LIKELIHOOD P(BP | Kelas)
A41: Kelas | B41: HIGH | C41: LOW | D41: NORMAL
A42: drugA | B42: =B33/E33 -> 1 | C42: =C33/E33 -> 0 | D42: =D33/E33 -> 0
A43: drugB | B43: =B34/E34 -> 1 | C43: =C34/E34 -> 0 | D43: =D34/E34 -> 0
A44: drugC | B44: =B35/E35 -> 0 | C44: =C35/E35 -> 1 | D44: =D35/E35 -> 0
A45: drugX | B45: =B36/E36 -> 0 | C45: =C36/E36 -> 0.3255814 | D45: =D36/E36 -> 0.6744186
A46: DrugY | B46: =B37/E37 -> 0.42465753 | C46: =C37/E37 -> 0.28767123 | D46: =D37/E37 -> 0.28767123
...

Sheet Prediksi & Evaluasi
A1: PREDIKSI NAIVE BAYES PADA 40 DATA TEST & EVALUASI AKURASI
A2: Data uji diambil dari sheet Splitting Data (Set=Test, baris 165-204). Posterior = Prior x Likelihood(Age) x Likelihood(BP) x Likelihood(Chol) x Likelihood(Na_to_K), dihitung dari tabel di sheet Prior & Likelihood.
A4: No | B4: Age | C4: BP | D4: Cholesterol | E4: Na_to_K | F4: ClassDrug (Aktual) | G4: Skor drugA | H4: Skor drugB | I4: Skor drugC | J4: Skor drugX | K4: Skor DrugY | L4: Prediksi | M4: Benar?
A5: 1 | B5: ='Splitting Data'!B165 -> YOUNG | C5: ='Splitting Data'!C165 -> HIGH | D5: ='Splitting Data'!D165 -> HIGH | E5: ='Splitting Data'!E165 -> NORMAL | F5: ='Splitting Data'!F165 -> drugA | G5: ='Prior & Likelihood'!C5*INDEX('Prior & Likelihood'!$B$24:$D$24,MATCH($B5,'Prior & Likelihood'!$B$23:$D$23,0))*INDEX('Prior & Likelihood'!$B$42:$D$42,MATCH($C5,'Prior & Likelihood'!$B$41:$D$41,0))*INDEX('Prior & Likelihood'!$B$60:$C$60,MATCH($D5,'Prior & Likelihood'!$B$59:$C$59,0))*INDEX('Prior & Likelihood'!$B$78:$D$78,MATCH($E5,'Prior & Likelihood'!$B$77:$D$77,0)) -> 0.0050925926 | H5: ='Prior & Likelihood'!C6*INDEX('Prior & Likelihood'!$B$25:$D$25,MATCH($B5,'Prior & Likelihood'!$B$23:$D$23,0))*INDEX('Prior & Likelihood'!$B$43:$D$43,MATCH($C5,'Prior & Likelihood'!$B$41:$D$41,0))*INDEX('Prior & Likelihood'!$B$61:$C$61,MATCH($D5,'Prior & Likelihood'!$B$59:$C$59,0))*INDEX('Prior & Likelihood'!$B$79:$D$79,MATCH($E5,'Prior & Likelihood'!$B$77:$D$77,0)) -> 0 | I5: ='Prior & Likelihood'!C7*INDEX('Prior & Likelihood'!$B$26:$D$26,MATCH($B5,'Prior & Likelihood'!$B$23:$D$23,0))*INDEX('Prior & Likelihood'!$B$44:$D$44,MATCH($C5,'Prior & Likelihood'!$B$41:$D$41,0))*INDEX('Prior & Likelihood'!$B$62:$C$62,MATCH($D5,'Prior & Likelihood'!$B$59:$C$59,0))*INDEX('Prior & Likelihood'!$B$80:$D$80,MATCH($E5,'Prior & Likelihood'!$B$77:$D$77,0)) -> 0 | J5: ='Prior & Likelihood'!C8*INDEX('Prior & Likelihood'!$B$27:$D$27,MATCH($B5,'Prior & Likelihood'!$B$23:$D$23,0))*INDEX('Prior & Likelihood'!$B$45:$D$45,MATCH($C5,'Prior & Likelihood'!$B$41:$D$41,0))*INDEX('Prior & Likelihood'!$B$63:$C$63,MATCH($D5,'Prior & Likelihood'!$B$59:$C$59,0))*INDEX('Prior & Likelihood'!$B$81:$D$81,MATCH($E5,'Prior & Likelihood'!$B$77:$D$77,0)) -> 0 | K5: ='Prior & Likelihood'!C9*INDEX('Prior & Likelihood'!$B$28:$D$28,MATCH($B5,'Prior & Likelihood'!$B$23:$D$23,0))*INDEX('Prior & Likelihood'!$B$46:$D$46,MATCH($C5,'Prior & Likelihood'!$B$41:$D$41,0))*INDEX('Prior & Likelihood'!$B$64:$C$64,MATCH($D5,'Prior & Likelihood'!$B$59:$C$59,0))*INDEX('Prior & Likelihood'!$B$82:$D$82,MATCH($E5,'Prior & Likelihood'!$B$77:$D$77,0)) -> 0.0078278552 | L5: =INDEX({"drugA","drugB","drugC","drugX","DrugY"},MATCH(MAX(G5:K5),G5:K5,0)) -> DrugY | M5: =IF(L5=F5,1,0) -> 0
A6: 2 | B6: ='Splitting Data'!B166 -> ADULT | C6: ='Splitting Data'!C166 -> HIGH | D6: ='Splitting Data'!D166 -> NORMAL | E6: ='Splitting Data'!E166 -> NORMAL | F6: ='Splitting Data'!F166 -> drugA | G6: ='Prior & Likelihood'!C5*INDEX('Prior & Likelihood'!$B$24:$D$24,MATCH($B6,'Prior & Likelihood'!$B$23:$D$23,0))*INDEX('Prior & Likelihood'!$B$42:$D$42,MATCH($C6,'Prior & Likelihood'!$B$41:$D$41,0))*INDEX('Prior & Likelihood'!$B$60:$C$60,MATCH($D6,'Prior & Likelihood'!$B$59:$C$59,0))*INDEX('Prior & Likelihood'!$B$78:$D$78,MATCH($E6,'Prior & Likelihood'!$B$77:$D$77,0)) -> 0.021219136 | H6: ='Prior & Likelihood'!C6*INDEX('Prior & Likelihood'!$B$25:$D$25,MATCH($B6,'Prior & Likelihood'!$B$23:$D$23,0))*INDEX('Prior & Likelihood'!$B$43:$D$43,MATCH($C6,'Prior & Likelihood'!$B$41:$D$41,0))*INDEX('Prior & Likelihood'!$B$61:$C$61,MATCH($D6,'Prior & Likelihood'!$B$59:$C$59,0))*INDEX('Prior & Likelihood'!$B$79:$D$79,MATCH($E6,'Prior & Likelihood'!$B$77:$D$77,0)) -> 0 | I6: ='Prior & Likelihood'!C7*INDEX('Prior & Likelihood'!$B$26:$D$26,MATCH($B6,'Prior & Likelihood'!$B$23:$D$23,0))*INDEX('Prior & Likelihood'!$B$44:$D$44,MATCH($C6,'Prior & Likelihood'!$B$41:$D$41,0))*INDEX('Prior & Likelihood'!$B$62:$C$62,MATCH($D6,'Prior & Likelihood'!$B$59:$C$59,0))*INDEX('Prior & Likelihood'!$B$80:$D$80,MATCH($E6,'Prior & Likelihood'!$B$77:$D$77,0)) -> 0 | J6: ='Prior & Likelihood'!C8*INDEX('Prior & Likelihood'!$B$27:$D$27,MATCH($B6,'Prior & Likelihood'!$B$23:$D$23,0))*INDEX('Prior & Likelihood'!$B$45:$D$45,MATCH($C6,'Prior & Likelihood'!$B$41:$D$41,0))*INDEX('Prior & Likelihood'!$B$63:$C$63,MATCH($D6,'Prior & Likelihood'!$B$59:$C$59,0))*INDEX('Prior & Likelihood'!$B$81:$D$81,MATCH($E6,'Prior & Likelihood'!$B$77:$D$77,0)) -> 0 | K6: ='Prior & Likelihood'!C9*INDEX('Prior & Likelihood'!$B$28:$D$28,MATCH($B6,'Prior & Likelihood'!$B$23:$D$23,0))*INDEX('Prior & Likelihood'!$B$46:$D$46,MATCH($C6,'Prior & Likelihood'!$B$41:$D$41,0))*INDEX('Prior & Likelihood'!$B$64:$C$64,MATCH($D6,'Prior & Likelihood'!$B$59:$C$59,0))*INDEX('Prior & Likelihood'!$B$82:$D$82,MATCH($E6,'Prior & Likelihood'!$B$77:$D$77,0)) -> 0.014698458 | L6: =INDEX({"drugA","drugB","drugC","drugX","DrugY"},MATCH(MAX(G6:K6),G6:K6,0)) -> drugA | M6: =IF(L6=F6,1,0) -> 1
A7: 3 | B7: ='Splitting Data'!B167 -> ADULT | C7: ='Splitting Data'!C167 -> HIGH | D7: ='Splitting Data'!D167 -> HIGH | E7: ='Splitting Data'!E167 -> NORMAL | F7: ='Splitting Data'!F167 -> drugA | G7: ='Prior & Likelihood'!C5*INDEX('Prior & Likelihood'!$B$24:$D$24,MATCH($B7,'Prior & Likelihood'!$B$23:$D$23,0))*INDEX('Prior & Likelihood'!$B$42:$D$42,MATCH($C7,'Prior & Likelihood'!$B$41:$D$41,0))*INDEX('Prior & Likelihood'!$B$60:$C$60,MATCH($D7,'Prior & Likelihood'!$B$59:$C$59,0))*INDEX('Prior & Likelihood'!$B$78:$D$78,MATCH($E7,'Prior & Likelihood'!$B$77:$D$77,0)) -> 0.016975309 | H7: ='Prior & Likelihood'!C6*INDEX('Prior & Likelihood'!$B$25:$D$25,MATCH($B7,'Prior & Likelihood'!$B$23:$D$23,0))*INDEX('Prior & Likelihood'!$B$43:$D$43,MATCH($C7,'Prior & Likelihood'!$B$41:$D$41,0))*INDEX('Prior & Likelihood'!$B$61:$C$61,MATCH($D7,'Prior & Likelihood'!$B$59:$C$59,0))*INDEX('Prior & Likelihood'!$B$79:$D$79,MATCH($E7,'Prior & Likelihood'!$B$77:$D$77,0)) -> 0 | I7: ='Prior & Likelihood'!C7*INDEX('Prior & Likelihood'!$B$26:$D$26,MATCH($B7,'Prior & Likelihood'!$B$23:$D$23,0))*INDEX('Prior & Likelihood'!$B$44:$D$44,MATCH($C7,'Prior & Likelihood'!$B$41:$D$41,0))*INDEX('Prior & Likelihood'!$B$62:$C$62,MATCH($D7,'Prior & Likelihood'!$B$59:$C$59,0))*INDEX('Prior & Likelihood'!$B$80:$D$80,MATCH($E7,'Prior & Likelihood'!$B$77:$D$77,0)) -> 0 | J7: ='Prior & Likelihood'!C8*INDEX('Prior & Likelihood'!$B$27:$D$27,MATCH($B7,'Prior & Likelihood'!$B$23:$D$23,0))*INDEX('Prior & Likelihood'!$B$45:$D$45,MATCH($C7,'Prior & Likelihood'!$B$41:$D$41,0))*INDEX('Prior & Likelihood'!$B$63:$C$63,MATCH($D7,'Prior & Likelihood'!$B$59:$C$59,0))*INDEX('Prior & Likelihood'!$B$81:$D$81,MATCH($E7,'Prior & Likelihood'!$B$77:$D$77,0)) -> 0 | K7: ='Prior & Likelihood'!C9*INDEX('Prior & Likelihood'!$B$28:$D$28,MATCH($B7,'Prior & Likelihood'!$B$23:$D$23,0))*INDEX('Prior & Likelihood'!$B$46:$D$46,MATCH($C7,'Prior & Likelihood'!$B$41:$D$41,0))*INDEX('Prior & Likelihood'!$B$64:$C$64,MATCH($D7,'Prior & Likelihood'!$B$59:$C$59,0))*INDEX('Prior & Likelihood'!$B$82:$D$82,MATCH($E7,'Prior & Likelihood'!$B$77:$D$77,0)) -> 0.016859996 | L7: =INDEX({"drugA","drugB","drugC","drugX","DrugY"},MATCH(MAX(G7:K7),G7:K7,0)) -> drugA | M7: =IF(L7=F7,1,0) -> 1
A8: 4 | B8: ='Splitting Data'!B168 -> ADULT | C8: ='Splitting Data'!C168 -> HIGH | D8: ='Splitting Data'!D168 -> HIGH | E8: ='Splitting Data'!E168 -> NORMAL | F8: ='Splitting Data'!F168 -> drugA | G8: ='Prior & Likelihood'!C5*INDEX('Prior & Likelihood'!$B$24:$D$24,MATCH($B8,'Prior & Likelihood'!$B$23:$D$23,0))*INDEX('Prior & Likelihood'!$B$42:$D$42,MATCH($C8,'Prior & Likelihood'!$B$41:$D$41,0))*INDEX('Prior & Likelihood'!$B$60:$C$60,MATCH($D8,'Prior & Likelihood'!$B$59:$C$59,0))*INDEX('Prior & Likelihood'!$B$78:$D$78,MATCH($E8,'Prior & Likelihood'!$B$77:$D$77,0)) -> 0.016975309 | H8: ='Prior & Likelihood'!C6*INDEX('Prior & Likelihood'!$B$25:$D$25,MATCH($B8,'Prior & Likelihood'!$B$23:$D$23,0))*INDEX('Prior & Likelihood'!$B$43:$D$43,MATCH($C8,'Prior & Likelihood'!$B$41:$D$41,0))*INDEX('Prior & Likelihood'!$B$61:$C$61,MATCH($D8,'Prior & Likelihood'!$B$59:$C$59,0))*INDEX('Prior & Likelihood'!$B$79:$D$79,MATCH($E8,'Prior & Likelihood'!$B$77:$D$77,0)) -> 0 | I8: ='Prior & Likelihood'!C7*INDEX('Prior & Likelihood'!$B$26:$D$26,MATCH($B8,'Prior & Likelihood'!$B$23:$D$23,0))*INDEX('Prior & Likelihood'!$B$44:$D$44,MATCH($C8,'Prior & Likelihood'!$B$41:$D$41,0))*INDEX('Prior & Likelihood'!$B$62:$C$62,MATCH($D8,'Prior & Likelihood'!$B$59:$C$59,0))*INDEX('Prior & Likelihood'!$B$80:$D$80,MATCH($E8,'Prior & Likelihood'!$B$77:$D$77,0)) -> 0 | J8: ='Prior & Likelihood'!C8*INDEX('Prior & Likelihood'!$B$27:$D$27,MATCH($B8,'Prior & Likelihood'!$B$23:$D$23,0))*INDEX('Prior & Likelihood'!$B$45:$D$45,MATCH($C8,'Prior & Likelihood'!$B$41:$D$41,0))*INDEX('Prior & Likelihood'!$B$63:$C$63,MATCH($D8,'Prior & Likelihood'!$B$59:$C$59,0))*INDEX('Prior & Likelihood'!$B$81:$D$81,MATCH($E8,'Prior & Likelihood'!$B$77:$D$77,0)) -> 0 | K8: ='Prior & Likelihood'!C9*INDEX('Prior & Likelihood'!$B$28:$D$28,MATCH($B8,'Prior & Likelihood'!$B$23:$D$23,0))*INDEX('Prior & Likelihood'!$B$46:$D$46,MATCH($C8,'Prior & Likelihood'!$B$41:$D$41,0))*INDEX('Prior & Likelihood'!$B$64:$C$64,MATCH($D8,'Prior & Likelihood'!$B$59:$C$59,0))*INDEX('Prior & Likelihood'!$B$82:$D$82,MATCH($E8,'Prior & Likelihood'!$B$77:$D$77,0)) -> 0.016859996 | L8: =INDEX({"drugA","drugB","drugC","drugX","DrugY"},MATCH(MAX(G8:K8),G8:K8,0)) -> drugA | M8: =IF(L8=F8,1,0) -> 1
A9: 5 | B9: ='Splitting Data'!B169 -> OLD | C9: ='Splitting Data'!C169 -> HIGH | D9: ='Splitting Data'!D169 -> HIGH | E9: ='Splitting Data'!E169 -> NORMAL | F9: ='Splitting Data'!F169 -> drugA | G9: ='Prior & Likelihood'!C5*INDEX('Prior & Likelihood'!$B$24:$D$24,MATCH($B9,'Prior & Likelihood'!$B$23:$D$23,0))*INDEX('Prior & Likelihood'!$B$42:$D$42,MATCH($C9,'Prior & Likelihood'!$B$41:$D$41,0))*INDEX('Prior & Likelihood'!$B$60:$C$60,MATCH($D9,'Prior & Likelihood'!$B$59:$C$59,0))*INDEX('Prior & Likelihood'!$B$78:$D$78,MATCH($E9,'Prior & Likelihood'!$B$77:$D$77,0)) -> 0.0084876543 | H9: ='Prior & Likelihood'!C6*INDEX('Prior & Likelihood'!$B$25:$D$25,MATCH($B9,'Prior & Likelihood'!$B$23:$D$23,0))*INDEX('Prior & Likelihood'!$B$43:$D$43,MATCH($C9,'Prior & Likelihood'!$B$41:$D$41,0))*INDEX('Prior & Likelihood'!$B$61:$C$61,MATCH($D9,'Prior & Likelihood'!$B$59:$C$59,0))*INDEX('Prior & Likelihood'!$B$79:$D$79,MATCH($E9,'Prior & Likelihood'!$B$77:$D$77,0)) -> 0.025961538 | I9: ='Prior & Likelihood'!C7*INDEX('Prior & Likelihood'!$B$26:$D$26,MATCH($B9,'Prior & Likelihood'!$B$23:$D$23,0))*INDEX('Prior & Likelihood'!$B$44:$D$44,MATCH($C9,'Prior & Likelihood'!$B$41:$D$41,0))*INDEX('Prior & Likelihood'!$B$62:$C$62,MATCH($D9,'Prior & Likelihood'!$B$59:$C$59,0))*INDEX('Prior & Likelihood'!$B$80:$D$80,MATCH($E9,'Prior & Likelihood'!$B$77:$D$77,0)) -> 0 | J9: ='Prior & Likelihood'!C8*INDEX('Prior & Likelihood'!$B$27:$D$27,MATCH($B9,'Prior & Likelihood'!$B$23:$D$23,0))*INDEX('Prior & Likelihood'!$B$45:$D$45,MATCH($C9,'Prior & Likelihood'!$B$41:$D$41,0))*INDEX('Prior & Likelihood'!$B$63:$C$63,MATCH($D9,'Prior & Likelihood'!$B$59:$C$59,0))*INDEX('Prior & Likelihood'!$B$81:$D$81,MATCH($E9,'Prior & Likelihood'!$B$77:$D$77,0)) -> 0 | K9: ='Prior & Likelihood'!C9*INDEX('Prior & Likelihood'!$B$28:$D$28,MATCH($B9,'Prior & Likelihood'!$B$23:$D$23,0))*INDEX('Prior & Likelihood'!$B$46:$D$46,MATCH($C9,'Prior & Likelihood'!$B$41:$D$41,0))*INDEX('Prior & Likelihood'!$B$64:$C$64,MATCH($D9,'Prior & Likelihood'!$B$59:$C$59,0))*INDEX('Prior & Likelihood'!$B$82:$D$82,MATCH($E9,'Prior & Likelihood'!$B$77:$D$77,0)) -> 0.019268567 | L9: =INDEX({"drugA","drugB","drugC","drugX","DrugY"},MATCH(MAX(G9:K9),G9:K9,0)) -> drugB | M9: =IF(L9=F9,1,0) -> 0
A10: 6 | B10: ='Splitting Data'!B170 -> OLD | C10: ='Splitting Data'!C170 -> HIGH | D10: ='Splitting Data'!D170 -> NORMAL | E10: ='Splitting Data'!E170 -> LOW | F10: ='Splitting Data'!F170 -> drugB | G10: ='Prior & Likelihood'!C5*INDEX('Prior & Likelihood'!$B$24:$D$24,MATCH($B10,'Prior & Likelihood'!$B$23:$D$23,0))*INDEX('Prior & Likelihood'!$B$42:$D$42,MATCH($C10,'Prior & Likelihood'!$B$41:$D$41,0))*INDEX('Prior & Likelihood'!$B$60:$C$60,MATCH($D10,'Prior & Likelihood'!$B$59:$C$59,0))*INDEX('Prior & Likelihood'!$B$78:$D$78,MATCH($E10,'Prior & Likelihood'!$B$77:$D$77,0)) -> 0.0048225309 | H10: ='Prior & Likelihood'!C6*INDEX('Prior & Likelihood'!$B$25:$D$25,MATCH($B10,'Prior & Likelihood'!$B$23:$D$23,0))*INDEX('Prior & Likelihood'!$B$43:$D$43,MATCH($C10,'Prior & Likelihood'!$B$41:$D$41,0))*INDEX('Prior & Likelihood'!$B$61:$C$61,MATCH($D10,'Prior & Likelihood'!$B$59:$C$59,0))*INDEX('Prior & Likelihood'!$B$79:$D$79,MATCH($E10,'Prior & Likelihood'!$B$77:$D$77,0)) -> 0.010096154 | I10: ='Prior & Likelihood'!C7*INDEX('Prior & Likelihood'!$B$26:$D$26,MATCH($B10,'Prior & Likelihood'!$B$23:$D$23,0))*INDEX('Prior & Likelihood'!$B$44:$D$44,MATCH($C10,'Prior & Likelihood'!$B$41:$D$41,0))*INDEX('Prior & Likelihood'!$B$62:$C$62,MATCH($D10,'Prior & Likelihood'!$B$59:$C$59,0))*INDEX('Prior & Likelihood'!$B$80:$D$80,MATCH($E10,'Prior & Likelihood'!$B$77:$D$77,0)) -> 0 | J10: ='Prior & Likelihood'!C8*INDEX('Prior & Likelihood'!$B$27:$D$27,MATCH($B10,'Prior & Likelihood'!$B$23:$D$23,0))*INDEX('Prior & Likelihood'!$B$45:$D$45,MATCH($C10,'Prior & Likelihood'!$B$41:$D$41,0))*INDEX('Prior & Likelihood'!$B$63:$C$63,MATCH($D10,'Prior & Likelihood'!$B$59:$C$59,0))*INDEX('Prior & Likelihood'!$B$81:$D$81,MATCH($E10,'Prior & Likelihood'!$B$77:$D$77,0)) -> 0 | K10: ='Prior & Likelihood'!C9*INDEX('Prior & Likelihood'!$B$28:$D$28,MATCH($B10,'Prior & Likelihood'!$B$23:$D$23,0))*INDEX('Prior & Likelihood'!$B$46:$D$46,MATCH($C10,'Prior & Likelihood'!$B$41:$D$41,0))*INDEX('Prior & Likelihood'!$B$64:$C$64,MATCH($D10,'Prior & Likelihood'!$B$59:$C$59,0))*INDEX('Prior & Likelihood'!$B$82:$D$82,MATCH($E10,'Prior & Likelihood'!$B$77:$D$77,0)) -> 0 | L10: =INDEX({"drugA","drugB","drugC","drugX","DrugY"},MATCH(MAX(G10:K10),G10:K10,0)) -> drugB | M10: =IF(L10=F10,1,0) -> 1
A11: 7 | B11: ='Splitting Data'!B171 -> OLD | C11: ='Splitting Data'!C171 -> HIGH | D11: ='Splitting Data'!D171 -> HIGH | E11: ='Splitting Data'!E171 -> NORMAL | F11: ='Splitting Data'!F171 -> drugB | G11: ='Prior & Likelihood'!C5*INDEX('Prior & Likelihood'!$B$24:$D$24,MATCH($B11,'Prior & Likelihood'!$B$23:$D$23,0))*INDEX('Prior & Likelihood'!$B$42:$D$42,MATCH($C11,'Prior & Likelihood'!$B$41:$D$41,0))*INDEX('Prior & Likelihood'!$B$60:$C$60,MATCH($D11,'Prior & Likelihood'!$B$59:$C$59,0))*INDEX('Prior & Likelihood'!$B$78:$D$78,MATCH($E11,'Prior & Likelihood'!$B$77:$D$77,0)) -> 0.0084876543 | H11: ='Prior & Likelihood'!C6*INDEX('Prior & Likelihood'!$B$25:$D$25,MATCH($B11,'Prior & Likelihood'!$B$23:$D$23,0))*INDEX('Prior & Likelihood'!$B$43:$D$43,MATCH($C11,'Prior & Likelihood'!$B$41:$D$41,0))*INDEX('Prior & Likelihood'!$B$61:$C$61,MATCH($D11,'Prior & Likelihood'!$B$59:$C$59,0))*INDEX('Prior & Likelihood'!$B$79:$D$79,MATCH($E11,'Prior & Likelihood'!$B$77:$D$77,0)) -> 0.025961538 | I11: ='Prior & Likelihood'!C7*INDEX('Prior & Likelihood'!$B$26:$D$26,MATCH($B11,'Prior & Likelihood'!$B$23:$D$23,0))*INDEX('Prior & Likelihood'!$B$44:$D$44,MATCH($C11,'Prior & Likelihood'!$B$41:$D$41,0))*INDEX('Prior & Likelihood'!$B$62:$C$62,MATCH($D11,'Prior & Likelihood'!$B$59:$C$59,0))*INDEX('Prior & Likelihood'!$B$80:$D$80,MATCH($E11,'Prior & Likelihood'!$B$77:$D$77,0)) -> 0 | J11: ='Prior & Likelihood'!C8*INDEX('Prior & Likelihood'!$B$27:$D$27,MATCH($B11,'Prior & Likelihood'!$B$23:$D$23,0))*INDEX('Prior & Likelihood'!$B$45:$D$45,MATCH($C11,'Prior & Likelihood'!$B$41:$D$41,0))*INDEX('Prior & Likelihood'!$B$63:$C$63,MATCH($D11,'Prior & Likelihood'!$B$59:$C$59,0))*INDEX('Prior & Likelihood'!$B$81:$D$81,MATCH($E11,'Prior & Likelihood'!$B$77:$D$77,0)) -> 0 | K11: ='Prior & Likelihood'!C9*INDEX('Prior & Likelihood'!$B$28:$D$28,MATCH($B11,'Prior & Likelihood'!$B$23:$D$23,0))*INDEX('Prior & Likelihood'!$B$46:$D$46,MATCH($C11,'Prior & Likelihood'!$B$41:$D$41,0))*INDEX('Prior & Likelihood'!$B$64:$C$64,MATCH($D11,'Prior & Likelihood'!$B$59:$C$59,0))*INDEX('Prior & Likelihood'!$B$82:$D$82,MATCH($E11,'Prior & Likelihood'!$B$77:$D$77,0)) -> 0.019268567 | L11: =INDEX({"drugA","drugB","drugC","drugX","DrugY"},MATCH(MAX(G11:K11),G11:K11,0)) -> drugB | M11: =IF(L11=F11,1,0) -> 1
A12: 8 | B12: ='Splitting Data'!B172 -> OLD | C12: ='Splitting Data'!C172 -> HIGH | D12: ='Splitting Data'!D172 -> HIGH | E12: ='Splitting Data'!E172 -> LOW | F12: ='Splitting Data'!F172 -> drugB | G12: ='Prior & Likelihood'!C5*INDEX('Prior & Likelihood'!$B$24:$D$24,MATCH($B12,'Prior & Likelihood'!$B$23:$D$23,0))*INDEX('Prior & Likelihood'!$B$42:$D$42,MATCH($C12,'Prior & Likelihood'!$B$41:$D$41,0))*INDEX('Prior & Likelihood'!$B$60:$C$60,MATCH($D12,'Prior & Likelihood'!$B$59:$C$59,0))*INDEX('Prior & Likelihood'!$B$78:$D$78,MATCH($E12,'Prior & Likelihood'!$B$77:$D$77,0)) -> 0.0038580247 | H12: ='Prior & Likelihood'!C6*INDEX('Prior & Likelihood'!$B$25:$D$25,MATCH($B12,'Prior & Likelihood'!$B$23:$D$23,0))*INDEX('Prior & Likelihood'!$B$43:$D$43,MATCH($C12,'Prior & Likelihood'!$B$41:$D$41,0))*INDEX('Prior & Likelihood'!$B$61:$C$61,MATCH($D12,'Prior & Likelihood'!$B$59:$C$59,0))*INDEX('Prior & Likelihood'!$B$79:$D$79,MATCH($E12,'Prior & Likelihood'!$B$77:$D$77,0)) -> 0.0086538462 | I12: ='Prior & Likelihood'!C7*INDEX('Prior & Likelihood'!$B$26:$D$26,MATCH($B12,'Prior & Likelihood'!$B$23:$D$23,0))*INDEX('Prior & Likelihood'!$B$44:$D$44,MATCH($C12,'Prior & Likelihood'!$B$41:$D$41,0))*INDEX('Prior & Likelihood'!$B$62:$C$62,MATCH($D12,'Prior & Likelihood'!$B$59:$C$59,0))*INDEX('Prior & Likelihood'!$B$80:$D$80,MATCH($E12,'Prior & Likelihood'!$B$77:$D$77,0)) -> 0 | J12: ='Prior & Likelihood'!C8*INDEX('Prior & Likelihood'!$B$27:$D$27,MATCH($B12,'Prior & Likelihood'!$B$23:$D$23,0))*INDEX('Prior & Likelihood'!$B$45:$D$45,MATCH($C12,'Prior & Likelihood'!$B$41:$D$41,0))*INDEX('Prior & Likelihood'!$B$63:$C$63,MATCH($D12,'Prior & Likelihood'!$B$59:$C$59,0))*INDEX('Prior & Likelihood'!$B$81:$D$81,MATCH($E12,'Prior & Likelihood'!$B$77:$D$77,0)) -> 0 | K12: ='Prior & Likelihood'!C9*INDEX('Prior & Likelihood'!$B$28:$D$28,MATCH($B12,'Prior & Likelihood'!$B$23:$D$23,0))*INDEX('Prior & Likelihood'!$B$46:$D$46,MATCH($C12,'Prior & Likelihood'!$B$41:$D$41,0))*INDEX('Prior & Likelihood'!$B$64:$C$64,MATCH($D12,'Prior & Likelihood'!$B$59:$C$59,0))*INDEX('Prior & Likelihood'!$B$82:$D$82,MATCH($E12,'Prior & Likelihood'!$B$77:$D$77,0)) -> 0 | L12: =INDEX({"drugA","drugB","drugC","drugX","DrugY"},MATCH(MAX(G12:K12),G12:K12,0)) -> drugB | M12: =IF(L12=F12,1,0) -> 1
A13: 9 | B13: ='Splitting Data'!B173 -> YOUNG | C13: ='Splitting Data'!C173 -> LOW | D13: ='Splitting Data'!D173 -> HIGH | E13: ='Splitting Data'!E173 -> NORMAL | F13: ='Splitting Data'!F173 -> drugC | G13: ='Prior & Likelihood'!C5*INDEX('Prior & Likelihood'!$B$24:$D$24,MATCH($B13,'Prior & Likelihood'!$B$23:$D$23,0))*INDEX('Prior & Likelihood'!$B$42:$D$42,MATCH($C13,'Prior & Likelihood'!$B$41:$D$41,0))*INDEX('Prior & Likelihood'!$B$60:$C$60,MATCH($D13,'Prior & Likelihood'!$B$59:$C$59,0))*INDEX('Prior & Likelihood'!$B$78:$D$78,MATCH($E13,'Prior & Likelihood'!$B$77:$D$77,0)) -> 0 | H13: ='Prior & Likelihood'!C6*INDEX('Prior & Likelihood'!$B$25:$D$25,MATCH($B13,'Prior & Likelihood'!$B$23:$D$23,0))*INDEX('Prior & Likelihood'!$B$43:$D$43,MATCH($C13,'Prior & Likelihood'!$B$41:$D$41,0))*INDEX('Prior & Likelihood'!$B$61:$C$61,MATCH($D13,'Prior & Likelihood'!$B$59:$C$59,0))*INDEX('Prior & Likelihood'!$B$79:$D$79,MATCH($E13,'Prior & Likelihood'!$B$77:$D$77,0)) -> 0 | I13: ='Prior & Likelihood'!C7*INDEX('Prior & Likelihood'!$B$26:$D$26,MATCH($B13,'Prior & Likelihood'!$B$23:$D$23,0))*INDEX('Prior & Likelihood'!$B$44:$D$44,MATCH($C13,'Prior & Likelihood'!$B$41:$D$41,0))*INDEX('Prior & Likelihood'!$B$62:$C$62,MATCH($D13,'Prior & Likelihood'!$B$59:$C$59,0))*INDEX('Prior & Likelihood'!$B$80:$D$80,MATCH($E13,'Prior & Likelihood'!$B$77:$D$77,0)) -> 0.0043269231 | J13: ='Prior & Likelihood'!C8*INDEX('Prior & Likelihood'!$B$27:$D$27,MATCH($B13,'Prior & Likelihood'!$B$23:$D$23,0))*INDEX('Prior & Likelihood'!$B$45:$D$45,MATCH($C13,'Prior & Likelihood'!$B$41:$D$41,0))*INDEX('Prior & Likelihood'!$B$63:$C$63,MATCH($D13,'Prior & Likelihood'!$B$59:$C$59,0))*INDEX('Prior & Likelihood'!$B$81:$D$81,MATCH($E13,'Prior & Likelihood'!$B$77:$D$77,0)) -> 0.0038727722 | K13: ='Prior & Likelihood'!C9*INDEX('Prior & Likelihood'!$B$28:$D$28,MATCH($B13,'Prior & Likelihood'!$B$23:$D$23,0))*INDEX('Prior & Likelihood'!$B$46:$D$46,MATCH($C13,'Prior & Likelihood'!$B$41:$D$41,0))*INDEX('Prior & Likelihood'!$B$64:$C$64,MATCH($D13,'Prior & Likelihood'!$B$59:$C$59,0))*INDEX('Prior & Likelihood'!$B$82:$D$82,MATCH($E13,'Prior & Likelihood'!$B$77:$D$77,0)) -> 0.0053027406 | L13: =INDEX({"drugA","drugB","drugC","drugX","DrugY"},MATCH(MAX(G13:K13),G13:K13,0)) -> DrugY | M13: =IF(L13=F13,1,0) -> 0
A14: 10 | B14: ='Splitting Data'!B174 -> YOUNG | C14: ='Splitting Data'!C174 -> LOW | D14: ='Splitting Data'!D174 -> HIGH | E14: ='Splitting Data'!E174 -> LOW | F14: ='Splitting Data'!F174 -> drugC | G14: ='Prior & Likelihood'!C5*INDEX('Prior & Likelihood'!$B$24:$D$24,MATCH($B14,'Prior & Likelihood'!$B$23:$D$23,0))*INDEX('Prior & Likelihood'!$B$42:$D$42,MATCH($C14,'Prior & Likelihood'!$B$41:$D$41,0))*INDEX('Prior & Likelihood'!$B$60:$C$60,MATCH($D14,'Prior & Likelihood'!$B$59:$C$59,0))*INDEX('Prior & Likelihood'!$B$78:$D$78,MATCH($E14,'Prior & Likelihood'!$B$77:$D$77,0)) -> 0 | H14: ='Prior & Likelihood'!C6*INDEX('Prior & Likelihood'!$B$25:$D$25,MATCH($B14,'Prior & Likelihood'!$B$23:$D$23,0))*INDEX('Prior & Likelihood'!$B$43:$D$43,MATCH($C14,'Prior & Likelihood'!$B$41:$D$41,0))*INDEX('Prior & Likelihood'!$B$61:$C$61,MATCH($D14,'Prior & Likelihood'!$B$59:$C$59,0))*INDEX('Prior & Likelihood'!$B$79:$D$79,MATCH($E14,'Prior & Likelihood'!$B$77:$D$77,0)) -> 0 | I14: ='Prior & Likelihood'!C7*INDEX('Prior & Likelihood'!$B$26:$D$26,MATCH($B14,'Prior & Likelihood'!$B$23:$D$23,0))*INDEX('Prior & Likelihood'!$B$44:$D$44,MATCH($C14,'Prior & Likelihood'!$B$41:$D$41,0))*INDEX('Prior & Likelihood'!$B$62:$C$62,MATCH($D14,'Prior & Likelihood'!$B$59:$C$59,0))*INDEX('Prior & Likelihood'!$B$80:$D$80,MATCH($E14,'Prior & Likelihood'!$B$77:$D$77,0)) -> 0.0014423077 | J14: ='Prior & Likelihood'!C8*INDEX('Prior & Likelihood'!$B$27:$D$27,MATCH($B14,'Prior & Likelihood'!$B$23:$D$23,0))*INDEX('Prior & Likelihood'!$B$45:$D$45,MATCH($C14,'Prior & Likelihood'!$B$41:$D$41,0))*INDEX('Prior & Likelihood'!$B$63:$C$63,MATCH($D14,'Prior & Likelihood'!$B$59:$C$59,0))*INDEX('Prior & Likelihood'!$B$81:$D$81,MATCH($E14,'Prior & Likelihood'!$B$77:$D$77,0)) -> 0.002525721 | K14: ='Prior & Likelihood'!C9*INDEX('Prior & Likelihood'!$B$28:$D$28,MATCH($B14,'Prior & Likelihood'!$B$23:$D$23,0))*INDEX('Prior & Likelihood'!$B$46:$D$46,MATCH($C14,'Prior & Likelihood'!$B$41:$D$41,0))*INDEX('Prior & Likelihood'!$B$64:$C$64,MATCH($D14,'Prior & Likelihood'!$B$59:$C$59,0))*INDEX('Prior & Likelihood'!$B$82:$D$82,MATCH($E14,'Prior & Likelihood'!$B$77:$D$77,0)) -> 0 | L14: =INDEX({"drugA","drugB","drugC","drugX","DrugY"},MATCH(MAX(G14:K14),G14:K14,0)) -> drugX | M14: =IF(L14=F14,1,0) -> 0
A15: 11 | B15: ='Splitting Data'!B175 -> ADULT | C15: ='Splitting Data'!C175 -> LOW | D15: ='Splitting Data'!D175 -> HIGH | E15: ='Splitting Data'!E175 -> NORMAL | F15: ='Splitting Data'!F175 -> drugC | G15: ='Prior & Likelihood'!C5*INDEX('Prior & Likelihood'!$B$24:$D$24,MATCH($B15,'Prior & Likelihood'!$B$23:$D$23,0))*INDEX('Prior & Likelihood'!$B$42:$D$42,MATCH($C15,'Prior & Likelihood'!$B$41:$D$41,0))*INDEX('Prior & Likelihood'!$B$60:$C$60,MATCH($D15,'Prior & Likelihood'!$B$59:$C$59,0))*INDEX('Prior & Likelihood'!$B$78:$D$78,MATCH($E15,'Prior & Likelihood'!$B$77:$D$77,0)) -> 0 | H15: ='Prior & Likelihood'!C6*INDEX('Prior & Likelihood'!$B$25:$D$25,MATCH($B15,'Prior & Likelihood'!$B$23:$D$23,0))*INDEX('Prior & Likelihood'!$B$43:$D$43,MATCH($C15,'Prior & Likelihood'!$B$41:$D$41,0))*INDEX('Prior & Likelihood'!$B$61:$C$61,MATCH($D15,'Prior & Likelihood'!$B$59:$C$59,0))*INDEX('Prior & Likelihood'!$B$79:$D$79,MATCH($E15,'Prior & Likelihood'!$B$77:$D$77,0)) -> 0 | I15: ='Prior & Likelihood'!C7*INDEX('Prior & Likelihood'!$B$26:$D$26,MATCH($B15,'Prior & Likelihood'!$B$23:$D$23,0))*INDEX('Prior & Likelihood'!$B$44:$D$44,MATCH($C15,'Prior & Likelihood'!$B$41:$D$41,0))*INDEX('Prior & Likelihood'!$B$62:$C$62,MATCH($D15,'Prior & Likelihood'!$B$59:$C$59,0))*INDEX('Prior & Likelihood'!$B$80:$D$80,MATCH($E15,'Prior & Likelihood'!$B$77:$D$77,0)) -> 0.012980769 | J15: ='Prior & Likelihood'!C8*INDEX('Prior & Likelihood'!$B$27:$D$27,MATCH($B15,'Prior & Likelihood'!$B$23:$D$23,0))*INDEX('Prior & Likelihood'!$B$45:$D$45,MATCH($C15,'Prior & Likelihood'!$B$41:$D$41,0))*INDEX('Prior & Likelihood'!$B$63:$C$63,MATCH($D15,'Prior & Likelihood'!$B$59:$C$59,0))*INDEX('Prior & Likelihood'!$B$81:$D$81,MATCH($E15,'Prior & Likelihood'!$B$77:$D$77,0)) -> 0.0051636963 | K15: ='Prior & Likelihood'!C9*INDEX('Prior & Likelihood'!$B$28:$D$28,MATCH($B15,'Prior & Likelihood'!$B$23:$D$23,0))*INDEX('Prior & Likelihood'!$B$46:$D$46,MATCH($C15,'Prior & Likelihood'!$B$41:$D$41,0))*INDEX('Prior & Likelihood'!$B$64:$C$64,MATCH($D15,'Prior & Likelihood'!$B$59:$C$59,0))*INDEX('Prior & Likelihood'!$B$82:$D$82,MATCH($E15,'Prior & Likelihood'!$B$77:$D$77,0)) -> 0.011421288 | L15: =INDEX({"drugA","drugB","drugC","drugX","DrugY"},MATCH(MAX(G15:K15),G15:K15,0)) -> drugC | M15: =IF(L15=F15,1,0) -> 1
A16: 12 | B16: ='Splitting Data'!B176 -> YOUNG | C16: ='Splitting Data'!C176 -> NORMAL | D16: ='Splitting Data'!D176 -> HIGH | E16: ='Splitting Data'!E176 -> NORMAL | F16: ='Splitting Data'!F176 -> drugX | G16: ='Prior & Likelihood'!C5*INDEX('Prior & Likelihood'!$B$24:$D$24,MATCH($B16,'Prior & Likelihood'!$B$23:$D$23,0))*INDEX('Prior & Likelihood'!$B$42:$D$42,MATCH($C16,'Prior & Likelihood'!$B$41:$D$41,0))*INDEX('Prior & Likelihood'!$B$60:$C$60,MATCH($D16,'Prior & Likelihood'!$B$59:$C$59,0))*INDEX('Prior & Likelihood'!$B$78:$D$78,MATCH($E16,'Prior & Likelihood'!$B$77:$D$77,0)) -> 0 | H16: ='Prior & Likelihood'!C6*INDEX('Prior & Likelihood'!$B$25:$D$25,MATCH($B16,'Prior & Likelihood'!$B$23:$D$23,0))*INDEX('Prior & Likelihood'!$B$43:$D$43,MATCH($C16,'Prior & Likelihood'!$B$41:$D$41,0))*INDEX('Prior & Likelihood'!$B$61:$C$61,MATCH($D16,'Prior & Likelihood'!$B$59:$C$59,0))*INDEX('Prior & Likelihood'!$B$79:$D$79,MATCH($E16,'Prior & Likelihood'!$B$77:$D$77,0)) -> 0 | I16: ='Prior & Likelihood'!C7*INDEX('Prior & Likelihood'!$B$26:$D$26,MATCH($B16,'Prior & Likelihood'!$B$23:$D$23,0))*INDEX('Prior & Likelihood'!$B$44:$D$44,MATCH($C16,'Prior & Likelihood'!$B$41:$D$41,0))*INDEX('Prior & Likelihood'!$B$62:$C$62,MATCH($D16,'Prior & Likelihood'!$B$59:$C$59,0))*INDEX('Prior & Likelihood'!$B$80:$D$80,MATCH($E16,'Prior & Likelihood'!$B$77:$D$77,0)) -> 0 | J16: ='Prior & Likelihood'!C8*INDEX('Prior & Likelihood'!$B$27:$D$27,MATCH($B16,'Prior & Likelihood'!$B$23:$D$23,0))*INDEX('Prior & Likelihood'!$B$45:$D$45,MATCH($C16,'Prior & Likelihood'!$B$41:$D$41,0))*INDEX('Prior & Likelihood'!$B$63:$C$63,MATCH($D16,'Prior & Likelihood'!$B$59:$C$59,0))*INDEX('Prior & Likelihood'!$B$81:$D$81,MATCH($E16,'Prior & Likelihood'!$B$77:$D$77,0)) -> 0.008022171 | K16: ='Prior & Likelihood'!C9*INDEX('Prior & Likelihood'!$B$28:$D$28,MATCH($B16,'Prior & Likelihood'!$B$23:$D$23,0))*INDEX('Prior & Likelihood'!$B$46:$D$46,MATCH($C16,'Prior & Likelihood'!$B$41:$D$41,0))*INDEX('Prior & Likelihood'!$B$64:$C$64,MATCH($D16,'Prior & Likelihood'!$B$59:$C$59,0))*INDEX('Prior & Likelihood'!$B$82:$D$82,MATCH($E16,'Prior & Likelihood'!$B$77:$D$77,0)) -> 0.0053027406 | L16: =INDEX({"drugA","drugB","drugC","drugX","DrugY"},MATCH(MAX(G16:K16),G16:K16,0)) -> drugX | M16: =IF(L16=F16,1,0) -> 1
A17: 13 | B17: ='Splitting Data'!B177 -> ADULT | C17: ='Splitting Data'!C177 -> NORMAL | D17: ='Splitting Data'!D177 -> HIGH | E17: ='Splitting Data'!E177 -> NORMAL | F17: ='Splitting Data'!F177 -> drugX | G17: ='Prior & Likelihood'!C5*INDEX('Prior & Likelihood'!$B$24:$D$24,MATCH($B17,'Prior & Likelihood'!$B$23:$D$23,0))*INDEX('Prior & Likelihood'!$B$42:$D$42,MATCH($C17,'Prior & Likelihood'!$B$41:$D$41,0))*INDEX('Prior & Likelihood'!$B$60:$C$60,MATCH($D17,'Prior & Likelihood'!$B$59:$C$59,0))*INDEX('Prior & Likelihood'!$B$78:$D$78,MATCH($E17,'Prior & Likelihood'!$B$77:$D$77,0)) -> 0 | H17: ='Prior & Likelihood'!C6*INDEX('Prior & Likelihood'!$B$25:$D$25,MATCH($B17,'Prior & Likelihood'!$B$23:$D$23,0))*INDEX('Prior & Likelihood'!$B$43:$D$43,MATCH($C17,'Prior & Likelihood'!$B$41:$D$41,0))*INDEX('Prior & Likelihood'!$B$61:$C$61,MATCH($D17,'Prior & Likelihood'!$B$59:$C$59,0))*INDEX('Prior & Likelihood'!$B$79:$D$79,MATCH($E17,'Prior & Likelihood'!$B$77:$D$77,0)) -> 0 | I17: ='Prior & Likelihood'!C7*INDEX('Prior & Likelihood'!$B$26:$D$26,MATCH($B17,'Prior & Likelihood'!$B$23:$D$23,0))*INDEX('Prior & Likelihood'!$B$44:$D$44,MATCH($C17,'Prior & Likelihood'!$B$41:$D$41,0))*INDEX('Prior & Likelihood'!$B$62:$C$62,MATCH($D17,'Prior & Likelihood'!$B$59:$C$59,0))*INDEX('Prior & Likelihood'!$B$80:$D$80,MATCH($E17,'Prior & Likelihood'!$B$77:$D$77,0)) -> 0 | J17: ='Prior & Likelihood'!C8*INDEX('Prior & Likelihood'!$B$27:$D$27,MATCH($B17,'Prior & Likelihood'!$B$23:$D$23,0))*INDEX('Prior & Likelihood'!$B$45:$D$45,MATCH($C17,'Prior & Likelihood'!$B$41:$D$41,0))*INDEX('Prior & Likelihood'!$B$63:$C$63,MATCH($D17,'Prior & Likelihood'!$B$59:$C$59,0))*INDEX('Prior & Likelihood'!$B$81:$D$81,MATCH($E17,'Prior & Likelihood'!$B$77:$D$77,0)) -> 0.010696228 | K17: ='Prior & Likelihood'!C9*INDEX('Prior & Likelihood'!$B$28:$D$28,MATCH($B17,'Prior & Likelihood'!$B$23:$D$23,0))*INDEX('Prior & Likelihood'!$B$46:$D$46,MATCH($C17,'Prior & Likelihood'!$B$41:$D$41,0))*INDEX('Prior & Likelihood'!$B$64:$C$64,MATCH($D17,'Prior & Likelihood'!$B$59:$C$59,0))*INDEX('Prior & Likelihood'!$B$82:$D$82,MATCH($E17,'Prior & Likelihood'!$B$77:$D$77,0)) -> 0.011421288 | L17: =INDEX({"drugA","drugB","drugC","drugX","DrugY"},MATCH(MAX(G17:K17),G17:K17,0)) -> DrugY | M17: =IF(L17=F17,1,0) -> 0
A18: 14 | B18: ='Splitting Data'!B178 -> ADULT | C18: ='Splitting Data'!C178 -> LOW | D18: ='Splitting Data'!D178 -> NORMAL | E18: ='Splitting Data'!E178 -> HIGH | F18: ='Splitting Data'!F178 -> drugX | G18: ='Prior & Likelihood'!C5*INDEX('Prior & Likelihood'!$B$24:$D$24,MATCH($B18,'Prior & Likelihood'!$B$23:$D$23,0))*INDEX('Prior & Likelihood'!$B$42:$D$42,MATCH($C18,'Prior & Likelihood'!$B$41:$D$41,0))*INDEX('Prior & Likelihood'!$B$60:$C$60,MATCH($D18,'Prior & Likelihood'!$B$59:$C$59,0))*INDEX('Prior & Likelihood'!$B$78:$D$78,MATCH($E18,'Prior & Likelihood'!$B$77:$D$77,0)) -> 0 | H18: ='Prior & Likelihood'!C6*INDEX('Prior & Likelihood'!$B$25:$D$25,MATCH($B18,'Prior & Likelihood'!$B$23:$D$23,0))*INDEX('Prior & Likelihood'!$B$43:$D$43,MATCH($C18,'Prior & Likelihood'!$B$41:$D$41,0))*INDEX('Prior & Likelihood'!$B$61:$C$61,MATCH($D18,'Prior & Likelihood'!$B$59:$C$59,0))*INDEX('Prior & Likelihood'!$B$79:$D$79,MATCH($E18,'Prior & Likelihood'!$B$77:$D$77,0)) -> 0 | I18: ='Prior & Likelihood'!C7*INDEX('Prior & Likelihood'!$B$26:$D$26,MATCH($B18,'Prior & Likelihood'!$B$23:$D$23,0))*INDEX('Prior & Likelihood'!$B$44:$D$44,MATCH($C18,'Prior & Likelihood'!$B$41:$D$41,0))*INDEX('Prior & Likelihood'!$B$62:$C$62,MATCH($D18,'Prior & Likelihood'!$B$59:$C$59,0))*INDEX('Prior & Likelihood'!$B$80:$D$80,MATCH($E18,'Prior & Likelihood'!$B$77:$D$77,0)) -> 0 | J18: ='Prior & Likelihood'!C8*INDEX('Prior & Likelihood'!$B$27:$D$27,MATCH($B18,'Prior & Likelihood'!$B$23:$D$23,0))*INDEX('Prior & Likelihood'!$B$45:$D$45,MATCH($C18,'Prior & Likelihood'!$B$41:$D$41,0))*INDEX('Prior & Likelihood'!$B$63:$C$63,MATCH($D18,'Prior & Likelihood'!$B$59:$C$59,0))*INDEX('Prior & Likelihood'!$B$81:$D$81,MATCH($E18,'Prior & Likelihood'!$B$77:$D$77,0)) -> 0.00171683 | K18: ='Prior & Likelihood'!C9*INDEX('Prior & Likelihood'!$B$28:$D$28,MATCH($B18,'Prior & Likelihood'!$B$23:$D$23,0))*INDEX('Prior & Likelihood'!$B$46:$D$46,MATCH($C18,'Prior & Likelihood'!$B$41:$D$41,0))*INDEX('Prior & Likelihood'!$B$64:$C$64,MATCH($D18,'Prior & Likelihood'!$B$59:$C$59,0))*INDEX('Prior & Likelihood'!$B$82:$D$82,MATCH($E18,'Prior & Likelihood'!$B$77:$D$77,0)) -> 0.013490156 | L18: =INDEX({"drugA","drugB","drugC","drugX","DrugY"},MATCH(MAX(G18:K18),G18:K18,0)) -> DrugY | M18: =IF(L18=F18,1,0) -> 0
A19: 15 | B19: ='Splitting Data'!B179 -> ADULT | C19: ='Splitting Data'!C179 -> NORMAL | D19: ='Splitting Data'!D179 -> NORMAL | E19: ='Splitting Data'!E179 -> LOW | F19: ='Splitting Data'!F179 -> drugX | G19: ='Prior & Likelihood'!C5*INDEX('Prior & Likelihood'!$B$24:$D$24,MATCH($B19,'Prior & Likelihood'!$B$23:$D$23,0))*INDEX('Prior & Likelihood'!$B$42:$D$42,MATCH($C19,'Prior & Likelihood'!$B$41:$D$41,0))*INDEX('Prior & Likelihood'!$B$60:$C$60,MATCH($D19,'Prior & Likelihood'!$B$59:$C$59,0))*INDEX('Prior & Likelihood'!$B$78:$D$78,MATCH($E19,'Prior & Likelihood'!$B$77:$D$77,0)) -> 0 | H19: ='Prior & Likelihood'!C6*INDEX('Prior & Likelihood'!$B$25:$D$25,MATCH($B19,'Prior & Likelihood'!$B$23:$D$23,0))*INDEX('Prior & Likelihood'!$B$43:$D$43,MATCH($C19,'Prior & Likelihood'!$B$41:$D$41,0))*INDEX('Prior & Likelihood'!$B$61:$C$61,MATCH($D19,'Prior & Likelihood'!$B$59:$C$59,0))*INDEX('Prior & Likelihood'!$B$79:$D$79,MATCH($E19,'Prior & Likelihood'!$B$77:$D$77,0)) -> 0 | I19: ='Prior & Likelihood'!C7*INDEX('Prior & Likelihood'!$B$26:$D$26,MATCH($B19,'Prior & Likelihood'!$B$23:$D$23,0))*INDEX('Prior & Likelihood'!$B$44:$D$44,MATCH($C19,'Prior & Likelihood'!$B$41:$D$41,0))*INDEX('Prior & Likelihood'!$B$62:$C$62,MATCH($D19,'Prior & Likelihood'!$B$59:$C$59,0))*INDEX('Prior & Likelihood'!$B$80:$D$80,MATCH($E19,'Prior & Likelihood'!$B$77:$D$77,0)) -> 0 | J19: ='Prior & Likelihood'!C8*INDEX('Prior & Likelihood'!$B$27:$D$27,MATCH($B19,'Prior & Likelihood'!$B$23:$D$23,0))*INDEX('Prior & Likelihood'!$B$45:$D$45,MATCH($C19,'Prior & Likelihood'!$B$41:$D$41,0))*INDEX('Prior & Likelihood'!$B$63:$C$63,MATCH($D19,'Prior & Likelihood'!$B$59:$C$59,0))*INDEX('Prior & Likelihood'!$B$81:$D$81,MATCH($E19,'Prior & Likelihood'!$B$77:$D$77,0)) -> 0.010668872 | K19: ='Prior & Likelihood'!C9*INDEX('Prior & Likelihood'!$B$28:$D$28,MATCH($B19,'Prior & Likelihood'!$B$23:$D$23,0))*INDEX('Prior & Likelihood'!$B$46:$D$46,MATCH($C19,'Prior & Likelihood'!$B$41:$D$41,0))*INDEX('Prior & Likelihood'!$B$64:$C$64,MATCH($D19,'Prior & Likelihood'!$B$59:$C$59,0))*INDEX('Prior & Likelihood'!$B$82:$D$82,MATCH($E19,'Prior & Likelihood'!$B$77:$D$77,0)) -> 0 | L19: =INDEX({"drugA","drugB","drugC","drugX","DrugY"},MATCH(MAX(G19:K19),G19:K19,0)) -> drugX | M19: =IF(L19=F19,1,0) -> 1
A20: 16 | B20: ='Splitting Data'!B180 -> ADULT | C20: ='Splitting Data'!C180 -> LOW | D20: ='Splitting Data'!D180 -> NORMAL | E20: ='Splitting Data'!E180 -> NORMAL | F20: ='Splitting Data'!F180 -> drugX | G20: ='Prior & Likelihood'!C5*INDEX('Prior & Likelihood'!$B$24:$D$24,MATCH($B20,'Prior & Likelihood'!$B$23:$D$23,0))*INDEX('Prior & Likelihood'!$B$42:$D$42,MATCH($C20,'Prior & Likelihood'!$B$41:$D$41,0))*INDEX('Prior & Likelihood'!$B$60:$C$60,MATCH($D20,'Prior & Likelihood'!$B$59:$C$59,0))*INDEX('Prior & Likelihood'!$B$78:$D$78,MATCH($E20,'Prior & Likelihood'!$B$77:$D$77,0)) -> 0 | H20: ='Prior & Likelihood'!C6*INDEX('Prior & Likelihood'!$B$25:$D$25,MATCH($B20,'Prior & Likelihood'!$B$23:$D$23,0))*INDEX('Prior & Likelihood'!$B$43:$D$43,MATCH($C20,'Prior & Likelihood'!$B$41:$D$41,0))*INDEX('Prior & Likelihood'!$B$61:$C$61,MATCH($D20,'Prior & Likelihood'!$B$59:$C$59,0))*INDEX('Prior & Likelihood'!$B$79:$D$79,MATCH($E20,'Prior & Likelihood'!$B$77:$D$77,0)) -> 0 | I20: ='Prior & Likelihood'!C7*INDEX('Prior & Likelihood'!$B$26:$D$26,MATCH($B20,'Prior & Likelihood'!$B$23:$D$23,0))*INDEX('Prior & Likelihood'!$B$44:$D$44,MATCH($C20,'Prior & Likelihood'!$B$41:$D$41,0))*INDEX('Prior & Likelihood'!$B$62:$C$62,MATCH($D20,'Prior & Likelihood'!$B$59:$C$59,0))*INDEX('Prior & Likelihood'!$B$80:$D$80,MATCH($E20,'Prior & Likelihood'!$B$77:$D$77,0)) -> 0 | J20: ='Prior & Likelihood'!C8*INDEX('Prior & Likelihood'!$B$27:$D$27,MATCH($B20,'Prior & Likelihood'!$B$23:$D$23,0))*INDEX('Prior & Likelihood'!$B$45:$D$45,MATCH($C20,'Prior & Likelihood'!$B$41:$D$41,0))*INDEX('Prior & Likelihood'!$B$63:$C$63,MATCH($D20,'Prior & Likelihood'!$B$59:$C$59,0))*INDEX('Prior & Likelihood'!$B$81:$D$81,MATCH($E20,'Prior & Likelihood'!$B$77:$D$77,0)) -> 0.0078974178 | K20: ='Prior & Likelihood'!C9*INDEX('Prior & Likelihood'!$B$28:$D$28,MATCH($B20,'Prior & Likelihood'!$B$23:$D$23,0))*INDEX('Prior & Likelihood'!$B$46:$D$46,MATCH($C20,'Prior & Likelihood'!$B$41:$D$41,0))*INDEX('Prior & Likelihood'!$B$64:$C$64,MATCH($D20,'Prior & Likelihood'!$B$59:$C$59,0))*INDEX('Prior & Likelihood'!$B$82:$D$82,MATCH($E20,'Prior & Likelihood'!$B$77:$D$77,0)) -> 0.0099570199 | L20: =INDEX({"drugA","drugB","drugC","drugX","DrugY"},MATCH(MAX(G20:K20),G20:K20,0)) -> DrugY | M20: =IF(L20=F20,1,0) -> 0
A21: 17 | B21: ='Splitting Data'!B181 -> OLD | C21: ='Splitting Data'!C181 -> NORMAL | D21: ='Splitting Data'!D181 -> NORMAL | E21: ='Splitting Data'!E181 -> LOW | F21: ='Splitting Data'!F181 -> drugX | G21: ='Prior & Likelihood'!C5*INDEX('Prior & Likelihood'!$B$24:$D$24,MATCH($B21,'Prior & Likelihood'!$B$23:$D$23,0))*INDEX('Prior & Likelihood'!$B$42:$D$42,MATCH($C21,'Prior & Likelihood'!$B$41:$D$41,0))*INDEX('Prior & Likelihood'!$B$60:$C$60,MATCH($D21,'Prior & Likelihood'!$B$59:$C$59,0))*INDEX('Prior & Likelihood'!$B$78:$D$78,MATCH($E21,'Prior & Likelihood'!$B$77:$D$77,0)) -> 0 | H21: ='Prior & Likelihood'!C6*INDEX('Prior & Likelihood'!$B$25:$D$25,MATCH($B21,'Prior & Likelihood'!$B$23:$D$23,0))*INDEX('Prior & Likelihood'!$B$43:$D$43,MATCH($C21,'Prior & Likelihood'!$B$41:$D$41,0))*INDEX('Prior & Likelihood'!$B$61:$C$61,MATCH($D21,'Prior & Likelihood'!$B$59:$C$59,0))*INDEX('Prior & Likelihood'!$B$79:$D$79,MATCH($E21,'Prior & Likelihood'!$B$77:$D$77,0)) -> 0 | I21: ='Prior & Likelihood'!C7*INDEX('Prior & Likelihood'!$B$26:$D$26,MATCH($B21,'Prior & Likelihood'!$B$23:$D$23,0))*INDEX('Prior & Likelihood'!$B$44:$D$44,MATCH($C21,'Prior & Likelihood'!$B$41:$D$41,0))*INDEX('Prior & Likelihood'!$B$62:$C$62,MATCH($D21,'Prior & Likelihood'!$B$59:$C$59,0))*INDEX('Prior & Likelihood'!$B$80:$D$80,MATCH($E21,'Prior & Likelihood'!$B$77:$D$77,0)) -> 0 | J21: ='Prior & Likelihood'!C8*INDEX('Prior & Likelihood'!$B$27:$D$27,MATCH($B21,'Prior & Likelihood'!$B$23:$D$23,0))*INDEX('Prior & Likelihood'!$B$45:$D$45,MATCH($C21,'Prior & Likelihood'!$B$41:$D$41,0))*INDEX('Prior & Likelihood'!$B$63:$C$63,MATCH($D21,'Prior & Likelihood'!$B$59:$C$59,0))*INDEX('Prior & Likelihood'!$B$81:$D$81,MATCH($E21,'Prior & Likelihood'!$B$77:$D$77,0)) -> 0.019559599 | K21: ='Prior & Likelihood'!C9*INDEX('Prior & Likelihood'!$B$28:$D$28,MATCH($B21,'Prior & Likelihood'!$B$23:$D$23,0))*INDEX('Prior & Likelihood'!$B$46:$D$46,MATCH($C21,'Prior & Likelihood'!$B$41:$D$41,0))*INDEX('Prior & Likelihood'!$B$64:$C$64,MATCH($D21,'Prior & Likelihood'!$B$59:$C$59,0))*INDEX('Prior & Likelihood'!$B$82:$D$82,MATCH($E21,'Prior & Likelihood'!$B$77:$D$77,0)) -> 0 | L21: =INDEX({"drugA","drugB","drugC","drugX","DrugY"},MATCH(MAX(G21:K21),G21:K21,0)) -> drugX | M21: =IF(L21=F21,1,0) -> 1
A22: 18 | B22: ='Splitting Data'!B182 -> OLD | C22: ='Splitting Data'!C182 -> LOW | D22: ='Splitting Data'!D182 -> NORMAL | E22: ='Splitting Data'!E182 -> NORMAL | F22: ='Splitting Data'!F182 -> drugX | G22: ='Prior & Likelihood'!C5*INDEX('Prior & Likelihood'!$B$24:$D$24,MATCH($B22,'Prior & Likelihood'!$B$23:$D$23,0))*INDEX('Prior & Likelihood'!$B$42:$D$42,MATCH($C22,'Prior & Likelihood'!$B$41:$D$41,0))*INDEX('Prior & Likelihood'!$B$60:$C$60,MATCH($D22,'Prior & Likelihood'!$B$59:$C$59,0))*INDEX('Prior & Likelihood'!$B$78:$D$78,MATCH($E22,'Prior & Likelihood'!$B$77:$D$77,0)) -> 0 | H22: ='Prior & Likelihood'!C6*INDEX('Prior & Likelihood'!$B$25:$D$25,MATCH($B22,'Prior & Likelihood'!$B$23:$D$23,0))*INDEX('Prior & Likelihood'!$B$43:$D$43,MATCH($C22,'Prior & Likelihood'!$B$41:$D$41,0))*INDEX('Prior & Likelihood'!$B$61:$C$61,MATCH($D22,'Prior & Likelihood'!$B$59:$C$59,0))*INDEX('Prior & Likelihood'!$B$79:$D$79,MATCH($E22,'Prior & Likelihood'!$B$77:$D$77,0)) -> 0 | I22: ='Prior & Likelihood'!C7*INDEX('Prior & Likelihood'!$B$26:$D$26,MATCH($B22,'Prior & Likelihood'!$B$23:$D$23,0))*INDEX('Prior & Likelihood'!$B$44:$D$44,MATCH($C22,'Prior & Likelihood'!$B$41:$D$41,0))*INDEX('Prior & Likelihood'!$B$62:$C$62,MATCH($D22,'Prior & Likelihood'!$B$59:$C$59,0))*INDEX('Prior & Likelihood'!$B$80:$D$80,MATCH($E22,'Prior & Likelihood'!$B$77:$D$77,0)) -> 0 | J22: ='Prior & Likelihood'!C8*INDEX('Prior & Likelihood'!$B$27:$D$27,MATCH($B22,'Prior & Likelihood'!$B$23:$D$23,0))*INDEX('Prior & Likelihood'!$B$45:$D$45,MATCH($C22,'Prior & Likelihood'!$B$41:$D$41,0))*INDEX('Prior & Likelihood'!$B$63:$C$63,MATCH($D22,'Prior & Likelihood'!$B$59:$C$59,0))*INDEX('Prior & Likelihood'!$B$81:$D$81,MATCH($E22,'Prior & Likelihood'!$B$77:$D$77,0)) -> 0.014478599 | K22: ='Prior & Likelihood'!C9*INDEX('Prior & Likelihood'!$B$28:$D$28,MATCH($B22,'Prior & Likelihood'!$B$23:$D$23,0))*INDEX('Prior & Likelihood'!$B$46:$D$46,MATCH($C22,'Prior & Likelihood'!$B$41:$D$41,0))*INDEX('Prior & Likelihood'!$B$64:$C$64,MATCH($D22,'Prior & Likelihood'!$B$59:$C$59,0))*INDEX('Prior & Likelihood'!$B$82:$D$82,MATCH($E22,'Prior & Likelihood'!$B$77:$D$77,0)) -> 0.011379451 | L22: =INDEX({"drugA","drugB","drugC","drugX","DrugY"},MATCH(MAX(G22:K22),G22:K22,0)) -> drugX | M22: =IF(L22=F22,1,0) -> 1
A23: 19 | B23: ='Splitting Data'!B183 -> OLD | C23: ='Splitting Data'!C183 -> NORMAL | D23: ='Splitting Data'!D183 -> HIGH | E23: ='Splitting Data'!E183 -> NORMAL | F23: ='Splitting Data'!F183 -> drugX | G23: ='Prior & Likelihood'!C5*INDEX('Prior & Likelihood'!$B$24:$D$24,MATCH($B23,'Prior & Likelihood'!$B$23:$D$23,0))*INDEX('Prior & Likelihood'!$B$42:$D$42,MATCH($C23,'Prior & Likelihood'!$B$41:$D$41,0))*INDEX('Prior & Likelihood'!$B$60:$C$60,MATCH($D23,'Prior & Likelihood'!$B$59:$C$59,0))*INDEX('Prior & Likelihood'!$B$78:$D$78,MATCH($E23,'Prior & Likelihood'!$B$77:$D$77,0)) -> 0 | H23: ='Prior & Likelihood'!C6*INDEX('Prior & Likelihood'!$B$25:$D$25,MATCH($B23,'Prior & Likelihood'!$B$23:$D$23,0))*INDEX('Prior & Likelihood'!$B$43:$D$43,MATCH($C23,'Prior & Likelihood'!$B$41:$D$41,0))*INDEX('Prior & Likelihood'!$B$61:$C$61,MATCH($D23,'Prior & Likelihood'!$B$59:$C$59,0))*INDEX('Prior & Likelihood'!$B$79:$D$79,MATCH($E23,'Prior & Likelihood'!$B$77:$D$77,0)) -> 0 | I23: ='Prior & Likelihood'!C7*INDEX('Prior & Likelihood'!$B$26:$D$26,MATCH($B23,'Prior & Likelihood'!$B$23:$D$23,0))*INDEX('Prior & Likelihood'!$B$44:$D$44,MATCH($C23,'Prior & Likelihood'!$B$41:$D$41,0))*INDEX('Prior & Likelihood'!$B$62:$C$62,MATCH($D23,'Prior & Likelihood'!$B$59:$C$59,0))*INDEX('Prior & Likelihood'!$B$80:$D$80,MATCH($E23,'Prior & Likelihood'!$B$77:$D$77,0)) -> 0 | J23: ='Prior & Likelihood'!C8*INDEX('Prior & Likelihood'!$B$27:$D$27,MATCH($B23,'Prior & Likelihood'!$B$23:$D$23,0))*INDEX('Prior & Likelihood'!$B$45:$D$45,MATCH($C23,'Prior & Likelihood'!$B$41:$D$41,0))*INDEX('Prior & Likelihood'!$B$63:$C$63,MATCH($D23,'Prior & Likelihood'!$B$59:$C$59,0))*INDEX('Prior & Likelihood'!$B$81:$D$81,MATCH($E23,'Prior & Likelihood'!$B$77:$D$77,0)) -> 0.019609751 | K23: ='Prior & Likelihood'!C9*INDEX('Prior & Likelihood'!$B$28:$D$28,MATCH($B23,'Prior & Likelihood'!$B$23:$D$23,0))*INDEX('Prior & Likelihood'!$B$46:$D$46,MATCH($C23,'Prior & Likelihood'!$B$41:$D$41,0))*INDEX('Prior & Likelihood'!$B$64:$C$64,MATCH($D23,'Prior & Likelihood'!$B$59:$C$59,0))*INDEX('Prior & Likelihood'!$B$82:$D$82,MATCH($E23,'Prior & Likelihood'!$B$77:$D$77,0)) -> 0.0130529 | L23: =INDEX({"drugA","drugB","drugC","drugX","DrugY"},MATCH(MAX(G23:K23),G23:K23,0)) -> drugX | M23: =IF(L23=F23,1,0) -> 1
A24: 20 | B24: ='Splitting Data'!B184 -> OLD | C24: ='Splitting Data'!C184 -> NORMAL | D24: ='Splitting Data'!D184 -> NORMAL | E24: ='Splitting Data'!E184 -> LOW | F24: ='Splitting Data'!F184 -> drugX | G24: ='Prior & Likelihood'!C5*INDEX('Prior & Likelihood'!$B$24:$D$24,MATCH($B24,'Prior & Likelihood'!$B$23:$D$23,0))*INDEX('Prior & Likelihood'!$B$42:$D$42,MATCH($C24,'Prior & Likelihood'!$B$41:$D$41,0))*INDEX('Prior & Likelihood'!$B$60:$C$60,MATCH($D24,'Prior & Likelihood'!$B$59:$C$59,0))*INDEX('Prior & Likelihood'!$B$78:$D$78,MATCH($E24,'Prior & Likelihood'!$B$77:$D$77,0)) -> 0 | H24: ='Prior & Likelihood'!C6*INDEX('Prior & Likelihood'!$B$25:$D$25,MATCH($B24,'Prior & Likelihood'!$B$23:$D$23,0))*INDEX('Prior & Likelihood'!$B$43:$D$43,MATCH($C24,'Prior & Likelihood'!$B$41:$D$41,0))*INDEX('Prior & Likelihood'!$B$61:$C$61,MATCH($D24,'Prior & Likelihood'!$B$59:$C$59,0))*INDEX('Prior & Likelihood'!$B$79:$D$79,MATCH($E24,'Prior & Likelihood'!$B$77:$D$77,0)) -> 0 | I24: ='Prior & Likelihood'!C7*INDEX('Prior & Likelihood'!$B$26:$D$26,MATCH($B24,'Prior & Likelihood'!$B$23:$D$23,0))*INDEX('Prior & Likelihood'!$B$44:$D$44,MATCH($C24,'Prior & Likelihood'!$B$41:$D$41,0))*INDEX('Prior & Likelihood'!$B$62:$C$62,MATCH($D24,'Prior & Likelihood'!$B$59:$C$59,0))*INDEX('Prior & Likelihood'!$B$80:$D$80,MATCH($E24,'Prior & Likelihood'!$B$77:$D$77,0)) -> 0 | J24: ='Prior & Likelihood'!C8*INDEX('Prior & Likelihood'!$B$27:$D$27,MATCH($B24,'Prior & Likelihood'!$B$23:$D$23,0))*INDEX('Prior & Likelihood'!$B$45:$D$45,MATCH($C24,'Prior & Likelihood'!$B$41:$D$41,0))*INDEX('Prior & Likelihood'!$B$63:$C$63,MATCH($D24,'Prior & Likelihood'!$B$59:$C$59,0))*INDEX('Prior & Likelihood'!$B$81:$D$81,MATCH($E24,'Prior & Likelihood'!$B$77:$D$77,0)) -> 0.019559599 | K24: ='Prior & Likelihood'!C9*INDEX('Prior & Likelihood'!$B$28:$D$28,MATCH($B24,'Prior & Likelihood'!$B$23:$D$23,0))*INDEX('Prior & Likelihood'!$B$46:$D$46,MATCH($C24,'Prior & Likelihood'!$B$41:$D$41,0))*INDEX('Prior & Likelihood'!$B$64:$C$64,MATCH($D24,'Prior & Likelihood'!$B$59:$C$59,0))*INDEX('Prior & Likelihood'!$B$82:$D$82,MATCH($E24,'Prior & Likelihood'!$B$77:$D$77,0)) -> 0 | L24: =INDEX({"drugA","drugB","drugC","drugX","DrugY"},MATCH(MAX(G24:K24),G24:K24,0)) -> drugX | M24: =IF(L24=F24,1,0) -> 1
A25: 21 | B25: ='Splitting Data'!B185 -> OLD | C25: ='Splitting Data'!C185 -> NORMAL | D25: ='Splitting Data'!D185 -> NORMAL | E25: ='Splitting Data'!E185 -> NORMAL | F25: ='Splitting Data'!F185 -> drugX | G25: ='Prior & Likelihood'!C5*INDEX('Prior & Likelihood'!$B$24:$D$24,MATCH($B25,'Prior & Likelihood'!$B$23:$D$23,0))*INDEX('Prior & Likelihood'!$B$42:$D$42,MATCH($C25,'Prior & Likelihood'!$B$41:$D$41,0))*INDEX('Prior & Likelihood'!$B$60:$C$60,MATCH($D25,'Prior & Likelihood'!$B$59:$C$59,0))*INDEX('Prior & Likelihood'!$B$78:$D$78,MATCH($E25,'Prior & Likelihood'!$B$77:$D$77,0)) -> 0 | H25: ='Prior & Likelihood'!C6*INDEX('Prior & Likelihood'!$B$25:$D$25,MATCH($B25,'Prior & Likelihood'!$B$23:$D$23,0))*INDEX('Prior & Likelihood'!$B$43:$D$43,MATCH($C25,'Prior & Likelihood'!$B$41:$D$41,0))*INDEX('Prior & Likelihood'!$B$61:$C$61,MATCH($D25,'Prior & Likelihood'!$B$59:$C$59,0))*INDEX('Prior & Likelihood'!$B$79:$D$79,MATCH($E25,'Prior & Likelihood'!$B$77:$D$77,0)) -> 0 | I25: ='Prior & Likelihood'!C7*INDEX('Prior & Likelihood'!$B$26:$D$26,MATCH($B25,'Prior & Likelihood'!$B$23:$D$23,0))*INDEX('Prior & Likelihood'!$B$44:$D$44,MATCH($C25,'Prior & Likelihood'!$B$41:$D$41,0))*INDEX('Prior & Likelihood'!$B$62:$C$62,MATCH($D25,'Prior & Likelihood'!$B$59:$C$59,0))*INDEX('Prior & Likelihood'!$B$80:$D$80,MATCH($E25,'Prior & Likelihood'!$B$77:$D$77,0)) -> 0 | J25: ='Prior & Likelihood'!C8*INDEX('Prior & Likelihood'!$B$27:$D$27,MATCH($B25,'Prior & Likelihood'!$B$23:$D$23,0))*INDEX('Prior & Likelihood'!$B$45:$D$45,MATCH($C25,'Prior & Likelihood'!$B$41:$D$41,0))*INDEX('Prior & Likelihood'!$B$63:$C$63,MATCH($D25,'Prior & Likelihood'!$B$59:$C$59,0))*INDEX('Prior & Likelihood'!$B$81:$D$81,MATCH($E25,'Prior & Likelihood'!$B$77:$D$77,0)) -> 0.029991384 | K25: ='Prior & Likelihood'!C9*INDEX('Prior & Likelihood'!$B$28:$D$28,MATCH($B25,'Prior & Likelihood'!$B$23:$D$23,0))*INDEX('Prior & Likelihood'!$B$46:$D$46,MATCH($C25,'Prior & Likelihood'!$B$41:$D$41,0))*INDEX('Prior & Likelihood'!$B$64:$C$64,MATCH($D25,'Prior & Likelihood'!$B$59:$C$59,0))*INDEX('Prior & Likelihood'!$B$82:$D$82,MATCH($E25,'Prior & Likelihood'!$B$77:$D$77,0)) -> 0.011379451 | L25: =INDEX({"drugA","drugB","drugC","drugX","DrugY"},MATCH(MAX(G25:K25),G25:K25,0)) -> drugX | M25: =IF(L25=F25,1,0) -> 1
A26: 22 | B26: ='Splitting Data'!B186 -> OLD | C26: ='Splitting Data'!C186 -> LOW | D26: ='Splitting Data'!D186 -> NORMAL | E26: ='Splitting Data'!E186 -> HIGH | F26: ='Splitting Data'!F186 -> drugX | G26: ='Prior & Likelihood'!C5*INDEX('Prior & Likelihood'!$B$24:$D$24,MATCH($B26,'Prior & Likelihood'!$B$23:$D$23,0))*INDEX('Prior & Likelihood'!$B$42:$D$42,MATCH($C26,'Prior & Likelihood'!$B$41:$D$41,0))*INDEX('Prior & Likelihood'!$B$60:$C$60,MATCH($D26,'Prior & Likelihood'!$B$59:$C$59,0))*INDEX('Prior & Likelihood'!$B$78:$D$78,MATCH($E26,'Prior & Likelihood'!$B$77:$D$77,0)) -> 0 | H26: ='Prior & Likelihood'!C6*INDEX('Prior & Likelihood'!$B$25:$D$25,MATCH($B26,'Prior & Likelihood'!$B$23:$D$23,0))*INDEX('Prior & Likelihood'!$B$43:$D$43,MATCH($C26,'Prior & Likelihood'!$B$41:$D$41,0))*INDEX('Prior & Likelihood'!$B$61:$C$61,MATCH($D26,'Prior & Likelihood'!$B$59:$C$59,0))*INDEX('Prior & Likelihood'!$B$79:$D$79,MATCH($E26,'Prior & Likelihood'!$B$77:$D$77,0)) -> 0 | I26: ='Prior & Likelihood'!C7*INDEX('Prior & Likelihood'!$B$26:$D$26,MATCH($B26,'Prior & Likelihood'!$B$23:$D$23,0))*INDEX('Prior & Likelihood'!$B$44:$D$44,MATCH($C26,'Prior & Likelihood'!$B$41:$D$41,0))*INDEX('Prior & Likelihood'!$B$62:$C$62,MATCH($D26,'Prior & Likelihood'!$B$59:$C$59,0))*INDEX('Prior & Likelihood'!$B$80:$D$80,MATCH($E26,'Prior & Likelihood'!$B$77:$D$77,0)) -> 0 | J26: ='Prior & Likelihood'!C8*INDEX('Prior & Likelihood'!$B$27:$D$27,MATCH($B26,'Prior & Likelihood'!$B$23:$D$23,0))*INDEX('Prior & Likelihood'!$B$45:$D$45,MATCH($C26,'Prior & Likelihood'!$B$41:$D$41,0))*INDEX('Prior & Likelihood'!$B$63:$C$63,MATCH($D26,'Prior & Likelihood'!$B$59:$C$59,0))*INDEX('Prior & Likelihood'!$B$81:$D$81,MATCH($E26,'Prior & Likelihood'!$B$77:$D$77,0)) -> 0.0031475216 | K26: ='Prior & Likelihood'!C9*INDEX('Prior & Likelihood'!$B$28:$D$28,MATCH($B26,'Prior & Likelihood'!$B$23:$D$23,0))*INDEX('Prior & Likelihood'!$B$46:$D$46,MATCH($C26,'Prior & Likelihood'!$B$41:$D$41,0))*INDEX('Prior & Likelihood'!$B$64:$C$64,MATCH($D26,'Prior & Likelihood'!$B$59:$C$59,0))*INDEX('Prior & Likelihood'!$B$82:$D$82,MATCH($E26,'Prior & Likelihood'!$B$77:$D$77,0)) -> 0.015417321 | L26: =INDEX({"drugA","drugB","drugC","drugX","DrugY"},MATCH(MAX(G26:K26),G26:K26,0)) -> DrugY | M26: =IF(L26=F26,1,0) -> 0
